<?xml version="1.0" encoding="utf-8"?><testsuites><testsuite name="pytest" errors="0" failures="1" skipped="0" tests="1" time="0.932" timestamp="2025-01-17T22:07:30.449889-03:00" hostname="DESKTOP-NK8V44U"><testcase classname="tests.unit.controllers.test_session_controller" name="test_get_session_found" time="0.021"><failure message="assert 404 == 200&#10; +  where 404 = &lt;WrapperTestResponse streamed [404 NOT FOUND]&gt;.status_code">client = &lt;FlaskClient &lt;Flask 'controllers.test_session_controller'&gt;&gt;, mock_table = &lt;MagicMock name='get_dynamodb_resource().Table()' id='1798880210112'&gt;

    def test_get_session_found(client, mock_table):
        """Test getting a session that exists."""
        mock_table.get_item.return_value = {"Item": {"id": "123", "data": "test"}}
        response = client.get("/api/sessions/123")
&gt;       assert response.status_code == 200
E       assert 404 == 200
E        +  where 404 = &lt;WrapperTestResponse streamed [404 NOT FOUND]&gt;.status_code

tests\unit\controllers\test_session_controller.py:32: AssertionError</failure></testcase></testsuite></testsuites>